Traceback (most recent call last):
  File "E:\ATF\../ATF\ATF\AdaptoFlux.py", line 554, in training
    last_collapse_values = np.apply_along_axis(self.collapse, axis=1, arr=self.last_values)
                           ^^^^^^^^^^^^^^^^^^^^^^^^^^^^^^^^^^^^^^^^^^^^^^^^^^^^^^^^^^^^^^^^
  File "C:\Users\15314\anaconda3\Lib\site-packages\numpy\lib\shape_base.py", line 379, in apply_along_axis
    res = asanyarray(func1d(inarr_view[ind0], *args, **kwargs))
                     ^^^^^^^^^^^^^^^^^^^^^^^^^^^^^^^^^^^^^^^^^
  File "E:\ATF\../ATF\ATF\AdaptoFlux.py", line 147, in collapse
    return self.custom_collapse_function(values)
           ^^^^^^^^^^^^^^^^^^^^^^^^^^^^^^^^^^^^^
  File "C:\Users\15314\anaconda3\Lib\site-packages\keras\src\utils\traceback_utils.py", line 122, in error_handler
    raise e.with_traceback(filtered_tb) from None
  File "C:\Users\15314\anaconda3\Lib\site-packages\keras\src\models\functional.py", line 272, in _adjust_input_rank
    raise ValueError(
ValueError: Exception encountered when calling Sequential.call().

[1mInvalid input shape for input Tensor("data:0", shape=(None,), dtype=float32). Expected shape (None, 28, 28), but input has incompatible shape (None,)[0m

Arguments received by Sequential.call():
  â€¢ inputs=tf.Tensor(shape=(None,), dtype=float32)
  â€¢ training=False
  â€¢ mask=None
